Workbook

Sheet SOFP
I2: Speedy Pioneer LTD | S2: =I2 -> Speedy Pioneer LTD | AC2: =I2 -> Speedy Pioneer LTD | AM2: =S2 -> Speedy Pioneer LTD | AU2: =AM2 -> Speedy Pioneer LTD
C3: MARITIME SOLUTIONS TECHNOLOGY SERVICES (HK) LIMITED | D3: MV PIONEER LADY | I3: M.V. "PIONEER LADY"-Shipmanagement Cost | S3: M.V. "PIONEER LADY"-Owner Cost | AC3: M.V. "PIONEER LADY"-Take Over Cost | AM3: M.V. "PIONEER LADY"-DryDocking Cost | AU3: M.V. "PIONEER LADY"-BMA Flag Change Cost
C4: 海事方案技術服務（香港）有限公司 | I4: (Ship Management Period: 15th Jul-2026 to 31th Dec-2026) | S4: (Owner Cost Period: 15th Jul-2026 to 31th Dec-2026) | AC4: (Take Over Vessel into Management: 15th Jul-2026 to 31th Jul-2026) | AM4: (DD Period: xxxxxxxxxxxxxxxxxxxxx) | AU4: (BMA Flag Change Period: 15th Jul-2026 to 01st Aug-2026)
C6: ="STATENMENT OF FINANCIAL POSITION As at "&TEXT(J6,"dd-mmm-yyyy") -> STATENMENT OF FINANCIAL POSITION As at 14-Oct-2026 | I6: BALANCE SHEET AS AT | J6: =TODAY() -> 46309 | S6: BALANCE SHEET AS AT | T6: =TODAY() -> 46309 | AC6: BALANCE SHEET AS AT | AD6: =TODAY() -> 46309 | AM6: BALANCE SHEET AS AT | AN6: =J6 -> 46309 | AU6: BALANCE SHEET AS AT | AV6: =R6 -> 0
E7: 2026/08/01 to
E8: =TODAY() -> 46309 | N8: US$ | P8: Notes | X8: US$ | Z8: Notes | AH8: US$ | AJ8: Notes | AR8: US$ | AT8: Notes | AZ8: US$ | BB8: Notes
D9: Note | E9: USD$ | I9: CURRENT ASSETS | S9: CURRENT ASSETS | AC9: CURRENT ASSETS | AM9: CURRENT ASSETS | AU9: CURRENT ASSETS
C10: Current assets
C11: Amount due from a director | D11: 6 | E11: =N17+X17+AH17+AR17+AZ17 -> 371554.52 | I11: Accounts Receivable | N11: =L12+L13 -> 0 | P11: 1 | S11: Accounts Receivable | V11: =V12+V13 -> 16371.04 | X11: =V11+V14+V15 -> 16371.04 | Z11: 1 | AC11: Accounts Receivable | AF11: =AF12+AF13 -> 12228.09 | AH11: =AF11+AF14+AF15 -> 12228.09 | AJ11: 1 | AM11: Accounts Receivable | AQ11: =SUM(AQ12:AQ13) -> 0 | AR11: =AQ11+AQ14+AQ15 -> 0 | AT11: 1 | AU11: Accounts Receivable | AY11: =SUM(AY12:AY13) -> 24996.94 | AZ11: =AY11+AY14+AY15 -> 24996.94 | BB11: 1
I12: Balance due from MSTS (cash surplus) | S12: Balance due from OWNER (cash surplus) | V12: 0 | AC12: Balance due from Take-over (cash surplus) | AM12: Balance due from Drydocking (cash surplus) | AU12: Balance due from BMA (cash surplus)
E13: =SUM(E11:E12) -> 371554.52 | I13: Actual accounts receivable | L13: =SUM('Shipmanagement RCVD'!K13:K15) -> 0 | S13: Actual accounts receivable | V13: ='Shipmanagement RCVD'!L2 -> 16371.04 | AC13: Actual accounts receivable | AF13: ='Shipmanagement RCVD'!J2 -> 12228.09 | AM13: Actual accounts receivable | AU13: Actual accounts receivable | AY13: ='Shipmanagement RCVD'!K2 -> 24996.94
C14: Less: Current liabilities | I14: Prepayments | L14: ='Shipmanagement RCVD'!I2 -> 317958.45 | N14: =L14 -> 317958.45 | P14: 1 | S14: Prepayments | Z14: 1 | AC14: Prepayments | AJ14: 1 | AM14: Prepayments | AP14: 0 | AQ14: 0 | AT14: 1 | AU14: Prepayments | AX14: 0 | AY14: 0 | BB14: 1
C15: Accured expenses | E15: =N26+X26+AH26+AR26+AZ26 -> 398259.75 | I15: Other Receivables | N15: =L15 -> 0 | S15: Other Receivables | AC15: Other Receivables | AM15: Other Receivables | AQ15: 0 | AU15: Other Receivables | AY15: 0
C16: 费用 + 待付款 + 拨付备用金 | E16: =N26+X26+AH26+AR26+AZ26 -> 398259.75
N17: =N14 -> 317958.45 | X17: =SUM(X11:X16) -> 16371.04 | AH17: =SUM(AH11:AH16) -> 12228.09 | AR17: =SUM(AR11:AR16) -> 0 | AZ17: =SUM(AZ11:AZ16) -> 24996.94
C18: Net Current Assets/(Liabilities) | E18: =E13-E16 -> -26705.231
I19: CURRENT LIABILITIES | S19: CURRENT LIABILITIES | AC19: CURRENT LIABILITIES | AM19: CURRENT LIABILITIES | AU19: CURRENT LIABILITIES
C21: Net Assets/(Liabilities) | E21: 0 | I21: Accounts Payable | N21: =L22+L23 -> 302102.79 | P21: 1 | S21: Accounts Payable | X21: =V22+V23 -> 36788.27 | Z21: 1 | AC21: Accounts Payable | AH21: =AF22+AF23 -> 18612.14 | AJ21: 1 | AM21: Accounts Payable | AQ21: =AQ22+AQ23 -> 0 | AR21: =AQ21+AQ24 -> 0 | AT21: 1 | AU21: Accounts Payable | AZ21: =AY21+AY23 -> 26341.66 | BB21: 1
I22: Balance due to MSTS (cash deficit) | S22: Balance due to MSTS (cash deficit) | AC22: Balance due to MSTS (cash deficit) | AM22: Balance due to MSTS (cash deficit) | AU22: Balance due to MSTS (cash deficit)
I23: Actual accounts payable | L23: =('Shipmanagement Cost'!X2+'Shipmanagement Cost'!Y2+'Shipmanagement Cost'!Z2+'Shipmanagement Cost'!AA2+'Shipmanagement Cost'!AB2+'Shipmanagement Cost'!T2) -> 302102.79 | S23: Actual accounts payable | V23: ='Owner Cost'!X2+'Owner Cost'!Y2+'Owner Cost'!Z2+'Owner Cost'!AA2+'Owner Cost'!AB2+'Owner Cost'!T2 -> 36788.27 | AC23: Actual accounts payable | AF23: ='Take-Over Cost'!X2+'Take-Over Cost'!Y2+'Take-Over Cost'!Z2+'Take-Over Cost'!AA2+'Take-Over Cost'!AB2+'Take-Over Cost'!T2 -> 18612.14 | AM23: Actual accounts payable | AU23: Actual accounts payable | AY23: ='BMA Flag Change'!Y2+'BMA Flag Change'!Z2+'BMA Flag Change'!AA2+'BMA Flag Change'!AB2+'BMA Flag Change'!AC2+'BMA Flag Change'!T2 -> 26341.66
C24: Equity | I24: Accruals | L24: =('Shipmanagement Cost'!W2) -> 6868.04 | N24: =L24 -> 6868.04 | P24: 1 | S24: Accruals | V24: ='Owner Cost'!W2 -> 0 | X24: =V24 -> 0 | Z24: 1 | AC24: Accruals | AF24: ='Take-Over Cost'!W2 -> 7546.85 | AH24: =AF24 -> 7546.85 | AJ24: 1 | AM24: Accruals | AR24: ='Take-Over Cost'!AG2 -> 0 | AT24: 1 | AU24: Accruals | AY24: ='BMA Flag Change'!X2 -> 0 | AZ24: ='BMA Flag Change'!X2 -> 0 | BB24: 1
C25: Share capital | E25: =E18-E21 -> -26705.231
C26: Issued & Fully Paid 10,000 ordinary shares | D26: 7 | E26: 0 | N26: =SUM(N21:N25) -> 308970.83 | X26: =SUM(X21:X25) -> 36788.27 | AH26: =SUM(AH21:AH25) -> 26158.99 | AR26: =SUM(AR21:AR25) -> 0 | AZ26: =SUM(AZ21:AZ25) -> 26341.66
C27: Retained earnings/(losses) | D27: 7 | E27: =E25-E26 -> -26705.231
E28: =SUM(E26:E27) -> -26705.231 | I28: NET CURRENT ASSETS / (LIABILITIES) | N28: =N17-N26 -> 8987.619 | S28: NET CURRENT ASSETS / (LIABILITIES) | X28: =X17-X26 -> -20417.23 | AC28: NET CURRENT ASSETS / (LIABILITIES) | AH28: =AH17-AH26 -> -13930.9 | AM28: NET CURRENT ASSETS / (LIABILITIES) | AR28: =AR17-AR26 -> 0 | AU28: NET CURRENT ASSETS / (LIABILITIES) | AZ28: =AZ17-AZ26 -> -1344.72
N31: US$ | X31: US$ | AH31: US$ | AR31: US$ | AZ31: US$
C32: Pioneer Lady 费用总结： | D32: 日期： | E32: =TODAY() -> 46309 | I32: FINANCED BY : | S32: FINANCED BY : | AC32: FINANCED BY : | AM32: FINANCED BY : | AU32: FINANCED BY :
C33: XCL Aires Ltd单船船东总收入 | D33: ='Shipmanagement RCVD'!I2+'Shipmanagement RCVD'!J2+'Shipmanagement RCVD'!K2+'Shipmanagement RCVD'!L2+'Shipmanagement RCVD'!M2 -> 371554.52
C34: Pioneer Lady 银行卡账户余额： | D34: ='Bank Verification'!J11 -> 92779.85 | I34: Prior Year Balance Surplus / (Deficit) Brought Forward | P34: 2 | S34: Prior Year Balance Surplus / (Deficit) Brought Forward | X34: 0 | Z34: 2 | AC34: Prior Year Balance Surplus / (Deficit) Brought Forward | AH34: 0 | AJ34: 2 | AM34: Prior Year Balance Surplus / (Deficit) Brought Forward | AR34: 0 | AT34: 2 | AU34: Prior Year Balance Surplus / (Deficit) Brought Forward | AZ34: 0 | BB34: 2
C35: Pioneer Lady 船长 CTM 余额： | D35: ='CTM Expenses List'!AA2 -> 29908 | E35: 非预算待收
C36: 1：Pioneer Lady 船管费用总计 | D36: ='Shipmanagement Cost'!AB2+'Shipmanagement Cost'!T2 -> 193372.59 | E36: 0 | I36: Operating Cost for the Period | L36: =N26 -> 308970.83 | N36: =L36 -> 308970.83 | P36: 2, 2A | S36: Operating Cost for the Period | V36: =X26 -> 36788.27 | X36: =V36 -> 36788.27 | Z36: 2, 2A | AC36: Operating Cost for the Period | AF36: =AH26 -> 26158.99 | AJ36: 2, 2A | AM36: Operating Cost for the Period | AP36: =AR28 -> 0 | AR36: =AP36 -> 0 | AT36: 2, 2A | AU36: Operating Cost for the Period | AX36: =AZ28 -> -1344.72 | AZ36: =AX36 -> -1344.72 | BB36: 2, 2A
C37: 2：Pioneer Lady 帮船东支付总计： | D37: ='Owner Cost'!AB2+'Owner Cost'!T2 -> 19700.04 | E37: =-'Shipmanagement RCVD'!G16 -> 20417.23 | I37: Payment on behalf of Owner | P37: 2 | S37: Payment on behalf of Owner | Z37: 2 | AC37: Payment on behalf of Owner | AF37: 0 | AJ37: 2 | AM37: Payment on behalf of Owner | AP37: 0 | AR37: =AP37 -> 0 | AT37: 2 | AU37: Payment on behalf of Owner | AX37: 0 | AZ37: =AX37 -> 0 | BB37: 2
C38: 3：Pioneer Lady 接船管费用总计： | D38: ='Take-Over Cost'!AB2+'Take-Over Cost'!T2 -> 12428.72 | E38: =-'Shipmanagement RCVD'!G15 -> 13930.9 | I38: Operating Fund Paid to Manager for the Period | L38: =N17 -> 317958.45 | N38: =L38 -> 317958.45 | P38: 2 | S38: Operating Fund Paid to Manager for the Period | V38: =X17 -> 16371.04 | X38: =V38 -> 16371.04 | Z38: 2 | AC38: Operating Fund Paid to Manager for the Period | AF38: =AH17 -> 12228.09 | AH38: 0 | AJ38: 2 | AM38: Operating Fund Paid to Manager for the Period | AP38: 0 | AR38: =AP38 -> 0 | AT38: 2 | AU38: Operating Fund Paid to Manager for the Period | AX38: 0 | AZ38: =AX38 -> 0 | BB38: 2
C39: 4：Pioneer Lady 换船旗为巴哈马费用总计 | D39: ='BMA Flag Change'!AC2+'BMA Flag Change'!T2 -> 26155.9 | E39: =-'Shipmanagement RCVD'!G14 -> 1344.72
C40: 5：Pioneer Lady修船干坞费用费用合计： | D40: ='DD Cost'!AB2+'DD Cost'!S2 -> 0 | E40: ='Shipmanagement RCVD'!M2 -> 0 | I40: AMOUNT DUE TO MSTS Shipmanagement (HK) Limited | N40: =N34-N36-N37+N38 -> 8987.619 | S40: AMOUNT DUE TO MSTS Shipmanagement (HK) Limited | X40: =X38-X36 -> -20417.23 | AC40: AMOUNT DUE TO MSTS Shipmanagement (HK) Limited | AH40: =AF38-AF36 -> -13930.9 | AM40: AMOUNT DUE TO MSTS Shipmanagement (HK) Limited | AR40: =SUM(AR34:AR39) -> 0 | AU40: AMOUNT DUE TO MSTS Shipmanagement (HK) Limited | AZ40: =SUM(AZ34:AZ39) -> -1344.72
C41: 平衡账（总支付−银行−费用−船上备用金）： | D41: =D33-D34-D35-D36-D37-D38-D39-D40 -> -2790.582 | X41: =X40-X28 -> 0 | AH41: =AH40-AH28 -> 0 | AR41: =AR40-AR28 -> 0 | AZ41: =AZ40-AZ28 -> 0
C42: 总结： | D42: =IF(OR(D41>1,D41<-1),"账目没做平","账面做平") -> 账目没做平
J44: =N26+X26+AH26+AZ26 -> 398259.75
J45: =E16 -> 398259.75
E47: =E25-'Bank Verification'!J9 -> -56613.231

Sheet Cost Checking
B2: MV Pioneer Lady | C2: PO | D2: Invoice | J2: Bank | K2: C/N | L2: C/N | N2: 日期 | O2: 收款方 | P2: 付款方 | Q2: 付款额 | R2: 船员工资-9 | S2: 船员GIB上船 | T2: 船员跟船 | U2: CTM | V2: CTM
B3: Description | C3: Amount | D3: Accrual | E3: Receiving | F3: Received | G3: Approved | H3: Paying | I3: Completed | J3: Charge | K3: Accural | L3: Profit(01)
N4: 日期 | O4: 收款方 | P4: 付款方 | Q4: 付款额 | R4: 船员工资-10 | S4: 代付WB工资
B5: Shipmanagement TT RCVD | C5: =C15+F15+I15+I18 -> 371554.52 | I5: ='Shipmanagement RCVD'!I2+'Shipmanagement RCVD'!K2+'Shipmanagement RCVD'!J2+'Shipmanagement RCVD'!L2 -> 371554.52 | J5: ='Shipmanagement RCVD'!O2 -> 40
B6: Shipmanagement Cost | C6: ='Shipmanagement Cost'!AC2 -> 308970.83 | D6: ='Shipmanagement Cost'!W2 -> 6868.04 | E6: ='Shipmanagement Cost'!X2 -> 0 | F6: ='Shipmanagement Cost'!Y2 -> 108730.2 | G6: ='Shipmanagement Cost'!Z2 -> 0 | H6: ='Shipmanagement Cost'!AA2 -> 0 | I6: ='Shipmanagement Cost'!AB2 -> 192452.06 | J6: ='Shipmanagement Cost'!T2 -> 920.53 | K6: ='Shipmanagement Cost'!N2 -> 0 | L6: ='Shipmanagement Cost'!O2 -> 0 | N6: 日期 | O6: 收款方 | P6: 付款方 | Q6: 付款额 | R6: 船员工资-10
B7: Owner Expenses | C7: ='Owner Cost'!AC2 -> 36788.27 | D7: ='Owner Cost'!W2 -> 0 | E7: ='Owner Cost'!X2 -> 0 | F7: ='Owner Cost'!Y2 -> 17088.23 | G7: ='Owner Cost'!Z2 -> 0 | H7: ='Owner Cost'!AA2 -> 0 | I7: ='Owner Cost'!AB2 -> 19680.04 | J7: ='Owner Cost'!T2 -> 20 | K7: ='Owner Cost'!N2 -> 0 | L7: ='Owner Cost'!O2 -> 0
B8: Take-Over Cost | C8: ='Take-Over Cost'!AC2 -> 26158.99 | D8: ='Take-Over Cost'!W2 -> 7546.85 | E8: ='Take-Over Cost'!X2 -> 0 | F8: ='Take-Over Cost'!Y2 -> 6183.42 | G8: ='Take-Over Cost'!Z2 -> 0 | H8: ='Take-Over Cost'!AA2 -> 0 | I8: ='Take-Over Cost'!AB2 -> 12376.24 | J8: ='Take-Over Cost'!T2 -> 52.48 | K8: ='Take-Over Cost'!N2 -> 0 | L8: ='Take-Over Cost'!O2 -> 0
B9: BMA Flag Change | C9: ='BMA Flag Change'!AD2 -> 26341.66 | D9: ='BMA Flag Change'!X2 -> 0 | E9: ='BMA Flag Change'!Y2 -> 0 | F9: ='BMA Flag Change'!Z2 -> 185.76 | G9: ='BMA Flag Change'!AA2 -> 0 | H9: ='BMA Flag Change'!AB2 -> 0 | I9: ='BMA Flag Change'!AC2 -> 26095 | J9: ='BMA Flag Change'!T2 -> 60.9
B10: Expenses Lists | C10: ='Expenses Lists'!AD2 -> 398259.75 | D10: ='Expenses Lists'!X2 -> 14414.89 | E10: ='Expenses Lists'!Y2 -> 0 | F10: ='Expenses Lists'!Z2 -> 132187.61 | G10: ='Expenses Lists'!AA2 -> 0 | H10: ='Expenses Lists'!AB2 -> 0 | I10: ='Expenses Lists'!AC2 -> 250603.34 | J10: ='Expenses Lists'!T2 -> 1053.91 | K10: ='Expenses Lists'!N2 -> 0 | L10: ='Expenses Lists'!O2 -> 0
B11: Diff in Expenses(must 0): | C11: =IF(AND((C10-C8-C6-C7-C9)>-1,(C10-C8-C6-C7-C9)<1),"账面持平",C10-C8-C6-C7-C9) -> 账面持平 | D11: =IF(AND((D10-D8-D6-D7-D9)>-1,(D10-D8-D6-D7-D9)<1),"账面持平",D10-D8-D6-D7-D9) -> 账面持平 | E11: =IF(AND((E10-E8-E6-E7-E9)>-1,(E10-E8-E6-E7-E9)<1),"账面持平",E10-E8-E6-E7-E9) -> 账面持平 | F11: =IF(AND((F10-F8-F6-F7-F9)>-1,(F10-F8-F6-F7-F9)<1),"账面持平",F10-F8-F6-F7-F9) -> 账面持平 | G11: =IF(AND((G10-G8-G6-G7-G9)>-1,(G10-G8-G6-G7-G9)<1),"账面持平",G10-G8-G6-G7-G9) -> 账面持平 | H11: =IF(AND((H10-H8-H6-H7-H9)>-1,(H10-H8-H6-H7-H9)<1),"账面持平",H10-H8-H6-H7-H9) -> 账面持平 | I11: =IF(AND((I10-I8-I6-I7-I9)>-1,(I10-I8-I6-I7-I9)<1),"账面持平",I10-I8-I6-I7-I9) -> 账面持平 | J11: =IF(AND((J10-J8-J6-J7-J9)>-1,(J10-J8-J6-J7-J9)<1),"账面持平",J10-J8-J6-J7-J9) -> 账面持平 | ... L11: =IF(AND((L10-L8-L6-L7-L9)>-1,(L10-L8-L6-L7-L9)<1),"账面持平",L10-L8-L6-L7-L9) -> 账面持平
B13: MV Pioneer Lady | C13: Shipmanagement Expenses | F13: Non-Budget, Owner Expenses | I13: Take-Over Expenses | L13: MSTS
B14: Real-time Account Position | C14: RCVD | D14: Cost | E14: Balance | F14: RCVD | G14: Cost | H14: Balance | I14: RCVD | J14: Cost | K14: Balance | L14: Profit(02)
B15: =C5-C10 -> -26705.231 | C15: ='Shipmanagement RCVD'!I2 -> 317958.45 | D15: ='Shipmanagement Cost'!W2+'Shipmanagement Cost'!X2+'Shipmanagement Cost'!Y2+'Shipmanagement Cost'!Z2+'Shipmanagement Cost'!AA2+'Shipmanagement Cost'!AB2+'Shipmanagement Cost'!T2 -> 308970.83 | E15: =C15-D15 -> 8987.619 | F15: ='Shipmanagement RCVD'!L2 -> 16371.04 | G15: ='Owner Cost'!W2+'Owner Cost'!X2+'Owner Cost'!Y2+'Owner Cost'!Z2+'Owner Cost'!AA2+'Owner Cost'!AB2+'Owner Cost'!T2 -> 36788.27 | H15: =F15-G15 -> -20417.23 | I15: ='Shipmanagement RCVD'!J2 -> 12228.09 | J15: ='Take-Over Cost'!W2+'Take-Over Cost'!X2+'Take-Over Cost'!Y2+'Take-Over Cost'!Z2+'Take-Over Cost'!AA2+'Take-Over Cost'!AB2+'Take-Over Cost'!T2 -> 26158.99 | K15: =I15-J15 -> -13930.9 | L15: ='Expenses Lists'!P2 -> 0
I16: BMA Flag Change, Owner Expenses
I17: RCVD | J17: Cost | K17: Balance
I18: ='Shipmanagement RCVD'!K2 -> 24996.94 | J18: ='BMA Flag Change'!X2+'BMA Flag Change'!Y2+'BMA Flag Change'!Z2+'BMA Flag Change'!AA2+'BMA Flag Change'!AB2+'BMA Flag Change'!AC2+'BMA Flag Change'!T2 -> 26341.66 | K18: =I18-J18 -> -1344.72

Sheet Bank Verification
D2: 美元 | E2: 7982933945 | F2: 入账
D3: 港币 | E3: 7982933945 | F3: 出账
D4: 欧元 | E4: 7982933945 | F4: 结息 | L4: 船队其他船 | M4: 实时单船账户 | N4: 日期
L5: Libra-XS
B6: =TODAY() -> 46309 | C6: 海事管理（MV PIONEER LADY）公司账目一览 | I6: PIONEER LADY银行卡vs账面: | J6: =TODAY() -> 46309 | L6: Pioneer Lady | M6: =J11 -> 92779.85
B7: Pioneer Lady | D7: MV PIONEER LADY（发票）付款进度概要 | I7: PIONEER LADY待支付: | J7: =SUM(C9:G9) -> 146602.5 | L7: CBL Spring
B8: 海事下订单 | C8: Accrual | D8: Receiving | E8: Received | F8: Approved | G8: Paying | H8: Completed | I8: PIONEER LADY(MSTS)收入: | J8: ='Cost Checking'!L15+'Cost Checking'!L10 -> 0 | L8: CBL Summer
B9: ='Cost Checking'!C7+'Cost Checking'!C6+'Cost Checking'!C8+'Cost Checking'!C9 -> 398259.75 | C9: ='Cost Checking'!D6+'Cost Checking'!D7+'Cost Checking'!D8+'Cost Checking'!D9 -> 14414.89 | D9: ='Cost Checking'!E6+'Cost Checking'!E7+'Cost Checking'!E8+'Cost Checking'!E9 -> 0 | E9: ='Cost Checking'!F6+'Cost Checking'!F7+'Cost Checking'!F8+'Cost Checking'!F9 -> 132187.61 | F9: ='Cost Checking'!G6+'Cost Checking'!G7+'Cost Checking'!G8+'Cost Checking'!G9 -> 0 | G9: ='Cost Checking'!H6+'Cost Checking'!H7+'Cost Checking'!H8+'Cost Checking'!H9 -> 0 | H9: ='Cost Checking'!I6+'Cost Checking'!I7+'Cost Checking'!I8+'Cost Checking'!I9 -> 250603.34 | I9: CTM ROB 船上现金资产: | J9: ='CTM Expenses List'!AA2 -> 29908 | L9: 船管账户现金流 | M9: =SUM(M5:M8) -> 92779.85
B10: MV PIONEER LADY (星展银行) 账户进/出账目记录 | H10: 银行付款手续费: | I10: PIONEER LADY单船财务平衡: | J10: =J11+J9-J7 -> -23914.649 | L10: 银行账户短息
B11: 序号 | C11: 日期 | D11: 币种 | E11: 账户 | F11: 入账/出账 | G11: 数额 | H11: =SUM(H12:H1110) -> 1133.91 | I11: PIONEER LADY银行卡PingPong余额: | J11: {=INDEX(J:J,MIN(IF(J12:J35<>"",ROW(J12:J35))))} -> 92779.85 | K11: 备注 | L11: 差别 | M11: =M9-M10 -> 92779.85
B14: 22 | C14: 46300 | D14: 美元 | E14: 7982933945 | F14: 入账 | G14: 9598.45 | H14: 0 | I14: =G14+H14 -> 9598.45 | J14: =IF(F14="入账",(J15+I14),(J15-I14)) -> 92779.85 | K14: PIONEER LADY
B15: 21 | C15: 46293 | D15: 美元 | E15: 7982933945 | F15: 入账 | G15: 9500 | H15: 20 | I15: =G15+H15 -> 9520 | J15: =IF(F15="入账",(J16+I15),(J16-I15)) -> 83181.4 | K15: PIONEER LADY付款失败
B16: 20 | C16: 46295 | D16: 美元 | E16: 7982933945 | F16: 出账 | G16: 2600 | H16: 20 | I16: =G16+H16 -> 2620 | J16: =IF(F16="入账",(J17+I16),(J17-I16)) -> 73661.4 | K16: Libra-XS
B17: 19 | C17: 46295 | D17: 美元 | E17: 7982933945 | F17: 出账 | G17: 30000 | H17: 120 | I17: =G17+H17 -> 30120 | J17: =IF(F17="入账",(J18+I17),(J18-I17)) -> 76281.4 | K17: PIONEER LADY
B18: 18 | C18: 46293 | D18: 美元 | E18: 7982933945 | F18: 出账 | G18: 1660 | H18: 20 | I18: =G18+H18 -> 1680 | J18: =IF(F18="入账",(J19+I18),(J19-I18)) -> 106401.4 | K18: PIONEER LADY
B19: 17 | C19: 46293 | D19: 美元 | E19: 7982933945 | F19: 出账 | G19: 9500 | H19: 20 | I19: =G19+H19 -> 9520 | J19: =IF(F19="入账",(J20+I19),(J20-I19)) -> 108081.4 | K19: PIONEER LADY
B20: 16 | C20: 46289 | D20: 美元 | E20: 7982933945 | F20: 出账 | G20: 4271.4 | H20: 20 | I20: =G20+H20 -> 4291.4 | J20: =IF(F20="入账",(J21+I20),(J21-I20)) -> 117601.4 | K20: PIONEER LADY
B21: 15 | C21: 46287 | D21: 美元 | E21: 7982933945 | F21: 出账 | G21: 1350 | H21: 20 | I21: =G21+H21 -> 1370 | J21: =IF(F21="入账",(J22+I21),(J22-I21)) -> 121892.8 | K21: PIONEER LADY
B22: 14 | C22: 46279 | D22: 美元 | E22: 7982933945 | F22: 出账 | G22: 30000 | H22: 120 | I22: 30120 | J22: =IF(F22="入账",(J23+I22),(J23-I22)) -> 123262.8 | K22: PIONEER LADY
B23: 13 | C23: 46276 | D23: 美元 | E23: 7982933945 | F23: 出账 | G23: 85263.12 | H23: 170.53 | I23: 85433.65 | J23: =IF(F23="入账",(J24+I23),(J24-I23)) -> 153382.8 | K23: PIONEER LADY
B24: 12 | C24: 46275 | D24: 美元 | E24: 7982933945 | F24: 入账 | G24: 202246.07 | H24: 20 | I24: 202226.07 | J24: =IF(F24="入账",(J25+I24),(J25-I24)) -> 238816.45 | K24: PIONEER LADY
B25: 11 | C25: 46273 | D25: 美元 | E25: 7982933945 | F25: 出账 | G25: 50000 | H25: 200 | I25: =G25+H25 -> 50200 | J25: =IF(F25="入账",(J26+I25),(J26-I25)) -> 36590.38 | K25: PIONEER LADY
B26: 10 | C26: 46268 | D26: 美元 | E26: 7982933945 | F26: 出账 | G26: 8121.24 | H26: 32.48 | I26: =G26+H26 -> 8153.72 | J26: =IF(F26="入账",(J27+I26),(J27-I26)) -> 86790.38 | K26: PIONEER LADY
B27: 9 | C27: 46265 | D27: 美元 | E27: 7982933945 | F27: 出账 | G27: 45000 | H27: 180 | I27: =G27+H27 -> 45180 | J27: =IF(F27="入账",(J28+I27),(J28-I27)) -> 94944.1 | K27: PIONEER LADY
B28: 8 | C28: 46265 | D28: 美元 | E28: 7982933945 | F28: 出账 | G28: 5000 | H28: 20 | I28: =G28+H28 -> 5020 | J28: =IF(F28="入账",(J29+I28),(J29-I28)) -> 140124.1 | K28: PIONEER LADY
B29: 7 | C29: 46261 | D29: 美元 | E29: 7982933945 | F29: 出账 | G29: 2000 | H29: 20 | I29: =G29+H29 -> 2020 | J29: =IF(F29="入账",(J30+I29),(J30-I29)) -> 145144.1 | K29: PIONEER LADY
B30: 6 | C30: 46259 | D30: 美元 | E30: 7982933945 | F30: 出账 | H30: 50 | I30: =G30+H30 -> 50 | J30: =IF(F30="入账",(J31+I30),(J31-I30)) -> 147164.1 | K30: PIONEER LADY
B31: 5 | C31: 46252 | D31: 美元 | E31: 7982933945 | F31: 出账 | G31: 10225 | H31: 40.9 | I31: =G31+H31 -> 10265.9 | J31: =IF(F31="入账",(J32+I31),(J32-I31)) -> 147214.1 | K31: PIONEER LADY
B32: 4 | C32: 46248 | D32: 美元 | E32: 7982933945 | F32: 出账 | G32: 2230 | H32: 20 | I32: =G32+H32 -> 2250 | J32: =IF(F32="入账",(J33+I32),(J33-I32)) -> 157480 | K32: PIONEER LADY | L32: =J11-E9-C9 -> -53822.649
B33: 3 | C33: 46248 | D33: 美元 | E33: 7982933945 | F33: 入账 | G33: 156350 | H33: 20 | I33: =G33-H33 -> 156330 | J33: =IF(F33="入账",(J34+I33),(J34-I33)) -> 159730 | K33: PIONEER LADY
B34: 2 | C34: 46227 | D34: 美元 | E34: 7982933945 | F34: 入账 | G34: 2100 | H34: 0 | I34: =G34+H34 -> 2100 | J34: =IF(F34="入账",(J35+I34),(J35-I34)) -> 3400 | K34: PIONEER LADY
B35: 1 | C35: 46225 | D35: 美元 | E35: 7982933945 | F35: 入账 | G35: 1300 | H35: 0 | I35: =G35+H35 -> 1300 | J35: =G35-H35 -> 1300 | K35: PIONEER LADY

Sheet Shipmanagement RCVD
B1: 入账日期 | C1: 类型 | D1: RQA | E1: Supplier | F1: PO Nos | G1: PO Current | H1: Rating | I1: Shipmanagement Amount(USD) | J1: Take-Over Account | K1: BMA Flag Change | L1: Owner Cost | M1: DD Cost | N1: Date | O1: Bank Charge | P1: Bank Charge
D2: Received | E2: Uploaded | F2: Approved | G2: Paying | H2: Completed | I2: =SUM(I3:I25) -> 317958.45 | J2: =SUM(J3:J25) -> 12228.09 | K2: =SUM(K3:K25) -> 24996.94 | L2: =SUM(L3:L25) -> 16371.04 | M2: =SUM(M3:M25) -> 0 | O2: =SUM(O3:O68) -> 40
B13: 46300 | C13: 顾问的费用-王总 | D13: Completed | E13: VENTURE MARITIME (HONG KONG) LIMITED | G13: 9598.45 | H13: 1 | I13: =G13*H13 -> 9598.45 | N13: =B13 -> 46300 | P13: HK Payee Advice_700a20625e0b477d8a20625e0b577dbb.pdf
C14: BMA Flag Change 9月份换船旗费用 | D14: Completed | E14: XCL ARIES LTD | G14: =SOFP!AZ40 -> -1344.72
C15: Take-Over Cost9月份船东费用 | D15: Completed | E15: XCL ARIES LTD | G15: =SOFP!AH40 -> -13930.9
C16: Owner Cost 9月份船东费用 | D16: Completed | E16: XCL ARIES LTD | G16: =SOFP!X40 -> -20417.23
C17: 船舶管理运营拨款10月份 | D17: Completed | E17: XCL ARIES LTD | G17: =5000*31 -> 155000
B18: 46275 | C18: BMA Flag Change 8月份换船旗费用 | D18: Completed | E18: XCL ARIES LTD | G18: 24996.94 | H18: 1 | K18: =G18 -> 24996.94 | N18: 46275 | P18: 63f3beff3842f8c1ab8873eb8078536d.pdf
B19: 46275 | C19: Take-Over Cost 8月份船东费用 | D19: Completed | E19: XCL ARIES LTD | G19: 12228.09 | H19: 1 | J19: =G19 -> 12228.09 | N19: 46275
B20: 46275 | C20: Owner Cost 8月份船东费用 | D20: Completed | E20: XCL ARIES LTD | G20: 15021.04 | H20: 1 | L20: =G20 -> 15021.04 | N20: 46275
B21: 46275 | C21: 船舶管理运营拨款9月份 | D21: Completed | E21: XCL ARIES LTD | G21: 150000 | H21: 1 | I21: =G21-O21 -> 149980 | N21: 46275 | O21: 20
B22: 46234 | C22: GRESIK加淡水100吨 | D22: Completed | E22: XCL ARIES LTD | G22: 1350 | H22: 1 | L22: 1350 | N22: =B22 -> 46234 | P22: 电子回单详情.pdf
B23: 46248 | C23: 船舶管理运营拨款8月份 | D23: Completed | E23: XCL ARIES LTD | G23: 155000 | H23: 1 | I23: =G23-O23 -> 154980 | N23: 46248 | O23: 20
B24: 46227 | C24: 接船费预付款 | D24: Completed | E24: 5 Ocean Ship Service (HK) Limited | G24: 2100 | H24: 1 | I24: =(G24*H24)-L24 -> 2100 | N24: 46227 | P24: Payment_Certificate_20260723210333.pdf
B25: 46225 | C25: 船舶维修服务-ACC Motor repair | D25: Completed | E25: 5 Ocean Ship Service (HK) Limited | G25: 1300 | H25: 1 | I25: =G25*H25 -> 1300 | N25: 46225 | P25: Payment_Certificate_20260722134815.pdf
B27: T/O Date | C27: Ship Management Expenses-Rcvd | D27: =I2 -> 317958.45
B28: 46218 | C28: Ship Take-over Expenses-Rcvd | D28: =J2 -> 12228.09
B29: Days | C29: Non Budget Expenses-Rcvd | D29: =L2 -> 16371.04
B30: =TODAY()-B28 -> 91 | C30: DD Expenses-Rcvd | D30: =K2 -> 24996.94
B31: Others | C31: Total Costs | D31: =SUM(D27:D30) -> 371554.52
C32: OPEX(Including O.B.O Payment) | D32: =(D27+D28+D29+D30)/(TODAY()-B28) -> 4083.0167

Sheet Expenses Lists
A1: 入账日期 | B1: 类型 | C1: RQA | D1: Supplier | E1: PO Nos | F1: Pay. Approval | G1: PO Current | H1: Rating | I1: PO Amount (USD) | J1: Account Code | K1: GRN/Date | L1: GRN Amount(USD) | M1: Invoice Amount(USD) | N1: C/N,Accural | O1: C/N Profit | P1: Profit | Q1: Invoice Date | R1: Due Date | S1: Payment Status | T1: Bank Charge | U1: Bank Slip | V1: Attachement | W1: Attachement | X1: Accrual | Y1: Receiving | Z1: Received | AA1: Approved | AB1: Paying | AC1: Completed
C2: Receiving | D2: Received | E2: Approved | G2: Paying | H2: Completed | I2: =SUM(I4:I101) -> 491536.62 | L2: =SUM(L4:L129) -> 491586.62 | M2: =SUM(M4:M129) -> 490602.02 | N2: =SUM(N83:N101) -> 0 | O2: =SUM(O83:O101) -> 0 | P2: =SUM(P83:P101) -> 0 | T2: =SUM(T4:T103) -> 1053.91 | V2: Invoices | W2: Credit Note | X2: =SUM(X4:X166) -> 14414.89 | Y2: =SUM(Y4:Y166) -> 0 | Z2: =SUM(Z4:Z166) -> 132187.61 | AA2: =SUM(AA4:AA166) -> 0 | AB2: =SUM(AB4:AB166) -> 0 | AC2: =SUM(AC4:AC166) -> 250603.34 | AD2: =SUM(X2:AC2)+T2 -> 398259.75
A3: 46265 | B3: CTM 月度船上结余 | D3: MSTS | G3: ='CTM Expenses List'!AA2 -> 29908 | H3: 1 | I3: =-G3 -> -29908 | J3: 6000007 | K3: 46265 | L3: =I3 -> -29908 | M3: =L3 -> -29908 | S3: Completed | X3: =IF(S3="Accrual",M3,"") | Y3: =IF(S3="Receiving",M3,"") | Z3: =IF(S3="Received",M3,"") | AA3: =IF(S3="Approved",M3,"") | AB3: =IF(S3="Paying",M3,"") | AC3: =IF(S3="Completed",M3,"") -> -29908
X4: =IF(S4="Accrual",M4,"") | Y4: =IF(S4="Receiving",M4,"") | Z4: =IF(S4="Received",M4,"") | AA4: =IF(S4="Approved",M4,"") | AB4: =IF(S4="Paying",M4,"") | AC4: =IF(S4="Completed",M4,"")
A5: 46309 | B5: 9月份船员工资+其他费用 | D5: Top Marine Limited | G5: 77881.96 | H5: 1 | I5: =G5*H5 -> 77881.96 | J5: 1000001 | K5: =A5 -> 46309 | L5: =I5 -> 77881.96 | M5: =L5 -> 77881.96 | S5: Received | X5: =IF(S5="Accrual",M5,"") | Y5: =IF(S5="Receiving",M5,"") | Z5: =IF(S5="Received",M5,"") -> 77881.96 | AA5: =IF(S5="Approved",M5,"") | AB5: =IF(S5="Paying",M5,"") | AC5: =IF(S5="Completed",M5,"")
A6: 46295 | B6: 帮Libra-XS支付巴哈马年度国旗国检验 | D6: SIMINTEC | G6: 2600 | H6: 1 | I6: =G6*H6 -> 2600 | L6: =I6 -> 2600 | M6: =L6 -> 2600 | S6: Completed | T6: 20 | X6: =IF(S6="Accrual",M6,"") | Y6: =IF(S6="Receiving",M6,"") | Z6: =IF(S6="Received",M6,"") | AA6: =IF(S6="Approved",M6,"") | AB6: =IF(S6="Paying",M6,"") | AC6: =IF(S6="Completed",M6,"") -> 2600
A7: 46295 | B7: 9月份客餐费用支出 | D7: CTM | G7: 249 | H7: 1 | I7: =G7*H7 -> 249 | J7: 6000002 | K7: =A7 -> 46295 | L7: =I7 -> 249 | M7: =L7 -> 249 | S7: Completed | X7: =IF(S7="Accrual",M7,"") | Y7: =IF(S7="Receiving",M7,"") | Z7: =IF(S7="Received",M7,"") | AA7: =IF(S7="Approved",M7,"") | AB7: =IF(S7="Paying",M7,"") | AC7: =IF(S7="Completed",M7,"") -> 249
A8: 46295 | B8: 9月份全船伙食费支出 | D8: CTM | G8: 5592 | H8: 1 | I8: =G8*H8 -> 5592 | J8: 1000002 | K8: =A8 -> 46295 | L8: =I8 -> 5592 | M8: =L8 -> 5592 | S8: Completed | X8: =IF(S8="Accrual",M8,"") | Y8: =IF(S8="Receiving",M8,"") | Z8: =IF(S8="Received",M8,"") | AA8: =IF(S8="Approved",M8,"") | AB8: =IF(S8="Paying",M8,"") | AC8: =IF(S8="Completed",M8,"") -> 5592
A9: 46293 | B9: 巴生港锚地检验陪同费 | D9: Silver Base Maritime Sdn. Bhd. | G9: 1660 | H9: 1 | I9: =G9*H9 -> 1660 | J9: 4000014 | L9: =I9 -> 1660 | M9: =L9 -> 1660 | S9: Completed | T9: 20 | X9: =IF(S9="Accrual",M9,"") | Y9: =IF(S9="Receiving",M9,"") | Z9: =IF(S9="Received",M9,"") | AA9: =IF(S9="Approved",M9,"") | AB9: =IF(S9="Paying",M9,"") | AC9: =IF(S9="Completed",M9,"") -> 1660
A10: 46293 | B10: 借款给 MULAU SHIPMANAGEMENT (HK) LIMITED付款失败 | D10: Maritime Solutions Technology Services (HK) Limited | G10: -9500 | H10: 1 | I10: =G10*H10 -> -9500 | L10: =I10 -> -9500 | M10: =L10 -> -9500 | S10: Completed | T10: -20 | AC10: =IF(S10="Completed",M10,"") -> -9500
A11: 46293 | B11: 借款给 MULAU SHIPMANAGEMENT (HK) LIMITED | D11: Maritime Solutions Technology Services (HK) Limited | G11: 9500 | H11: 1 | I11: =G11*H11 -> 9500 | L11: =I11 -> 9500 | M11: =L11 -> 9500 | S11: Completed | T11: 20 | X11: =IF(S11="Accrual",M11,"") | Y11: =IF(S11="Receiving",M11,"") | Z11: =IF(S11="Received",M11,"") | AA11: =IF(S11="Approved",M11,"") | AB11: =IF(S11="Paying",M11,"") | AC11: =IF(S11="Completed",M11,"") -> 9500
A12: 46289 | B12: PIONEER LADY_海卫通卫星通信服务费 | D12: Marinesat海卫通网络科技有限公司 | G12: 8487.98 | H12: 0.149 | I12: =G12*H12 -> 1264.709 | J12: 6000017 | L12: =I12 -> 1264.709 | M12: =L12 -> 1264.709 | S12: Received | X12: =IF(S12="Accrual",M12,"") | Y12: =IF(S12="Receiving",M12,"") | Z12: =IF(S12="Received",M12,"") -> 1264.709 | AA12: =IF(S12="Approved",M12,"") | AB12: =IF(S12="Paying",M12,"") | AC12: =IF(S12="Completed",M12,"")
A13: 46289 | B13: PIONEER LADY_办公租赁费+薪资 | G13: =157197.89+70000 -> 227197.89 | H13: 0.14937855 | I13: =G13*H13 -> 33938.492 | J13: 6000016 | L13: =I13 -> 33938.492 | M13: =L13 -> 33938.492 | S13: Completed | T13: 120 | X13: =IF(S13="Accrual",M13,"") | Y13: =IF(S13="Receiving",M13,"") | Z13: =IF(S13="Received",M13,"") | AA13: =IF(S13="Approved",M13,"") | AB13: =IF(S13="Paying",M13,"") | AC13: =IF(S13="Completed",M13,"") -> 33938.492
A14: 46286 | B14: Termination of FME | D14: The LISCR Trust Company | G14: 300 | H14: 1 | I14: =G14*H14 -> 300 | J14: 9000005 | L14: =I14 -> 300 | M14: =L14 -> 300 | Q14: 46285 | S14: Completed | X14: =IF(S14="Accrual",M14,"") | Y14: =IF(S14="Receiving",M14,"") | Z14: =IF(S14="Received",M14,"") | AA14: =IF(S14="Approved",M14,"") | AB14: =IF(S14="Paying",M14,"") | AC14: =IF(S14="Completed",M14,"") -> 300
A15: 46286 | B15: LISCR Annual Registration+Agent Fee | D15: The LISCR Trust Company | G15: 1050 | H15: 1 | I15: =G15*H15 -> 1050 | J15: 9000005 | L15: =I15 -> 1050 | M15: =L15 -> 1050 | Q15: 46183 | R15: 46254 | S15: Completed | T15: 20 | X15: =IF(S15="Accrual",M15,"") | Y15: =IF(S15="Receiving",M15,"") | Z15: =IF(S15="Received",M15,"") | AA15: =IF(S15="Approved",M15,"") | AB15: =IF(S15="Paying",M15,"") | AC15: =IF(S15="Completed",M15,"") -> 1050
A16: 46286 | B16: 柯凯敏青岛就医及路费支出 | D16: CTM | G16: 149 | H16: 1 | I16: =G16*H16 -> 149 | J16: 7000009 | K16: =A16 -> 46286 | L16: =I16 -> 149 | M16: =L16 -> 149 | S16: Completed | X16: =IF(S16="Accrual",M16,"") | Y16: =IF(S16="Receiving",M16,"") | Z16: =IF(S16="Received",M16,"") | AA16: =IF(S16="Approved",M16,"") | AB16: =IF(S16="Paying",M16,"") | AC16: =IF(S16="Completed",M16,"") -> 149
A17: 46286 | B17: 678月季度自修奖金支出 | D17: CTM | G17: 3000 | H17: 1 | I17: =G17*H17 -> 3000 | J17: 10000007 | K17: =A17 -> 46286 | L17: =I17 -> 3000 | M17: =L17 -> 3000 | S17: Completed | X17: =IF(S17="Accrual",M17,"") | Y17: =IF(S17="Receiving",M17,"") | Z17: =IF(S17="Received",M17,"") | AA17: =IF(S17="Approved",M17,"") | AB17: =IF(S17="Paying",M17,"") | AC17: =IF(S17="Completed",M17,"") -> 3000
A18: 46285 | B18: 青岛通用物料申请 | C18: DPILT26009 | D18: DanTecs (HK) Marine Solutions Limited | E18: PILDT26009 | G18: 4113.43 | H18: 1 | I18: 4113.43 | J18: 2000005 | L18: 4113.43 | M18: =L18 -> 4113.43 | Q18: 46283 | R18: 46313 | S18: Received | X18: =IF(S18="Accrual",M18,"") | Y18: =IF(S18="Receiving",M18,"") | Z18: =IF(S18="Received",M18,"") -> 4113.43 | AA18: =IF(S18="Approved",M18,"") | AB18: =IF(S18="Paying",M18,"") | AC18: =IF(S18="Completed",M18,"")
A19: 46284 | B19: 青岛港加工缆车刹车操作杆费用-周琦支付 | G19: 522.51 | H19: 1 | I19: =G19*H19 -> 522.51 | J19: 4000002 | L19: =I19 -> 522.51 | M19: =L19 -> 522.51 | S19: Completed | X19: =IF(S19="Accrual",M19,"") | Y19: =IF(S19="Receiving",M19,"") | Z19: =IF(S19="Received",M19,"") | AA19: =IF(S19="Approved",M19,"") | AB19: =IF(S19="Paying",M19,"") | AC19: =IF(S19="Completed",M19,"") -> 522.51
A20: 46284 | B20: 青岛代理收 SPRO费用300美元 | D20: CTM | G20: 300 | H20: 1 | I20: =G20*H20 -> 300 | J20: 6000001 | K20: =A20 -> 46284 | L20: =I20 -> 300 | M20: =L20 -> 300 | S20: Completed | X20: =IF(S20="Accrual",M20,"") | Y20: =IF(S20="Receiving",M20,"") | Z20: =IF(S20="Received",M20,"") | AA20: =IF(S20="Approved",M20,"") | AB20: =IF(S20="Paying",M20,"") | AC20: =IF(S20="Completed",M20,"") -> 300
A21: 46284 | B21: 青岛购买BondedStore香烟 | D21: CTM | G21: 1010 | H21: 1 | I21: =G21*H21 -> 1010 | J21: 6000020 | K21: =A21 -> 46284 | L21: =I21 -> 1010 | M21: =L21 -> 1010 | S21: Completed | X21: =IF(S21="Accrual",M21,"") | Y21: =IF(S21="Receiving",M21,"") | Z21: =IF(S21="Received",M21,"") | AA21: =IF(S21="Approved",M21,"") | AB21: =IF(S21="Paying",M21,"") | AC21: =IF(S21="Completed",M21,"") -> 1010
A22: 46283 | B22: 日照购买Bonded Store酒水等支出 | D22: CTM | G22: 293 | H22: 1 | I22: =G22*H22 -> 293 | J22: 6000020 | K22: =A22 -> 46283 | L22: =I22 -> 293 | M22: =L22 -> 293 | S22: Completed | X22: =IF(S22="Accrual",M22,"") | Y22: =IF(S22="Receiving",M22,"") | Z22: =IF(S22="Received",M22,"") | AA22: =IF(S22="Approved",M22,"") | AB22: =IF(S22="Paying",M22,"") | AC22: =IF(S22="Completed",M22,"") -> 293
A23: 46281 | B23: 青岛港冰机修理 | D23: GORDON MARINE REFRIGERATION CO.,LTD, | G23: 28650 | H23: 0.149 | I23: =G23*H23 -> 4268.85 | J23: 4000005 | L23: =I23 -> 4268.85 | M23: =L23 -> 4268.85 | S23: Accrual | X23: =IF(S23="Accrual",M23,"") -> 4268.85 | Y23: =IF(S23="Receiving",M23,"") | Z23: =IF(S23="Received",M23,"") | AA23: =IF(S23="Approved",M23,"") | AB23: =IF(S23="Paying",M23,"") | AC23: =IF(S23="Completed",M23,"")
A24: 46281 | B24: 冰种+码头管理费 | C24: EPILT26004 | D24: DanTecs (HK) Marine Solutions Limited | E24: PILET26004 | G24: 560 | H24: 1 | I24: 560 | J24: 2000008 | L24: 560 | M24: 560 | S24: Received | Z24: =IF(S24="Received",M24,"") -> 560
B25: 冲回原船管欠船员7月份伙食费支出 | D25: MSTS | G25: -1544 | H25: 1 | I25: -1544 | J25: 6000007 | L25: -1544 | M25: -1544 | X25: =IF(S25="Accrual",M25,"") | Y25: =IF(S25="Receiving",M25,"") | Z25: =IF(S25="Received",M25,"") | AA25: =IF(S25="Approved",M25,"") | AB25: =IF(S25="Paying",M25,"") | AC25: =IF(S25="Completed",M25,"")
A26: 46284 | B26: 办公室杂项费用 | G26: 298.31 | H26: 1 | I26: =G26*H26 -> 298.31 | J26: 6000016 | L26: =I26 -> 298.31 | M26: =L26 -> 298.31 | S26: Completed | X26: =IF(S26="Accrual",M26,"") | Y26: =IF(S26="Receiving",M26,"") | Z26: =IF(S26="Received",M26,"") | AA26: =IF(S26="Approved",M26,"") | AB26: =IF(S26="Paying",M26,"") | AC26: =IF(S26="Completed",M26,"") -> 298.31
A27: 46274 | B27: Pioneer Lady岚桥港值班及交通补贴-周琦RMB3541.02 | G27: 522.51 | H27: 1 | I27: =G27*H27 -> 522.51 | J27: 6000006 | L27: =I27 -> 522.51 | M27: =L27 -> 522.51 | X27: =IF(S27="Accrual",M27,"") | Y27: =IF(S27="Receiving",M27,"") | Z27: =IF(S27="Received",M27,"") | AA27: =IF(S27="Approved",M27,"") | AB27: =IF(S27="Paying",M27,"") | AC27: =IF(S27="Completed",M27,"")
A28: 46272 | B28: 青岛港采购油漆 | C28: DPILT26008 | D28: DanTecs (HK) Marine Solutions Limited | E28: PILDT26008 | G28: 12974.8 | H28: 1 | I28: =G28*H28 -> 12974.8 | J28: 2000004 | L28: =I28 -> 12974.8 | M28: =L28 -> 12974.8 | Q28: 46283 | R28: 46313 | S28: Received | X28: =IF(S28="Accrual",M28,"") | Y28: =IF(S28="Receiving",M28,"") | Z28: =IF(S28="Received",M28,"") -> 12974.8 | AA28: =IF(S28="Approved",M28,"") | AB28: =IF(S28="Paying",M28,"") | AC28: =IF(S28="Completed",M28,"")
A29: 46272 | B29: 岚桥港舱盖 UT 超声波检验费-Owner Paid | D29: REASUN INSURANCE SURVEYORS & ADJUSTERS CO., LTD | E29: SY2026080042LND | G29: 1200 | H29: 1 | I29: =G29*H29 -> 1200 | J29: 4000014 | K29: 46266 | L29: =I29 -> 1200 | M29: =L29 -> 1200 | Q29: 46266 | R29: 46268 | X29: =IF(S29="Accrual",M29,"") | Y29: =IF(S29="Receiving",M29,"") | Z29: =IF(S29="Received",M29,"") | AA29: =IF(S29="Approved",M29,"") | AB29: =IF(S29="Paying",M29,"") | AC29: =IF(S29="Completed",M29,"")
A30: 46269 | B30: BMA 换旗相关证书费用 | D30: Top Marine Limited | G30: 2565 | H30: 1 | I30: =G30*H30 -> 2565 | J30: 9000000 | L30: =I30 -> 2565 | M30: =L30 -> 2565 | S30: Completed | X30: =IF(S30="Accrual",M30,"") | Y30: =IF(S30="Receiving",M30,"") | Z30: =IF(S30="Received",M30,"") | AA30: =IF(S30="Approved",M30,"") | AB30: =IF(S30="Paying",M30,"") | AC30: =IF(S30="Completed",M30,"") -> 2565
A31: 46269 | B31: 8 月份船员海外换班费 | D31: Top Marine Limited | G31: 12501.04 | H31: 1 | I31: =G31*H31 -> 12501.04 | J31: 1000090 | L31: =I31 -> 12501.04 | M31: =L31 -> 12501.04 | S31: Completed | X31: =IF(S31="Accrual",M31,"") | Y31: =IF(S31="Receiving",M31,"") | Z31: =IF(S31="Received",M31,"") | AA31: =IF(S31="Approved",M31,"") | AB31: =IF(S31="Paying",M31,"") | AC31: =IF(S31="Completed",M31,"") -> 12501.04
A32: 46269 | B32: 8 月份船员工资 | D32: Top Marine Limited | G32: 70197.08 | H32: 1 | I32: =G32*H32 -> 70197.08 | J32: 1000001 | L32: =I32 -> 70197.08 | M32: =L32 -> 70197.08 | S32: Completed | T32: 170.53 | X32: =IF(S32="Accrual",M32,"") | Y32: =IF(S32="Receiving",M32,"") | Z32: =IF(S32="Received",M32,"") | AA32: =IF(S32="Approved",M32,"") | AB32: =IF(S32="Paying",M32,"") | AC32: =IF(S32="Completed",M32,"") -> 70197.08
A33: 46267 | B33: 提现后的差额费用 | G33: 2301.47 | H33: 1 | I33: =G33*H33 -> 2301.47 | J33: 6000016 | L33: =I33 -> 2301.47 | M33: =L33 -> 2301.47 | S33: Completed | X33: =IF(S33="Accrual",M33,"") | Y33: =IF(S33="Receiving",M33,"") | Z33: =IF(S33="Received",M33,"") | AA33: =IF(S33="Approved",M33,"") | AB33: =IF(S33="Paying",M33,"") | AC33: =IF(S33="Completed",M33,"") -> 2301.47
A34: 46267 | B34: 办公室费用 | G34: 10292.19 | H34: 1 | I34: =G34*H34 -> 10292.19 | J34: 6000013 | L34: =I34 -> 10292.19 | M34: =L34 -> 10292.19 | S34: Completed | X34: =IF(S34="Accrual",M34,"") | Y34: =IF(S34="Receiving",M34,"") | Z34: =IF(S34="Received",M34,"") | AA34: =IF(S34="Approved",M34,"") | AB34: =IF(S34="Paying",M34,"") | AC34: =IF(S34="Completed",M34,"") -> 10292.19
A35: 46267 | B35: 通信数据流量费 | D35: TELEOCEAN INC | G35: 44.8 | H35: 1 | I35: =G35*H35 -> 44.8 | J35: 6000017 | K35: 46266 | L35: =I35 -> 44.8 | M35: =L35 -> 44.8 | Q35: 46266 | R35: 46281 | S35: Received | X35: =IF(S35="Accrual",M35,"") | Y35: =IF(S35="Receiving",M35,"") | Z35: =IF(S35="Received",M35,"") -> 44.8 | AA35: =IF(S35="Approved",M35,"") | AB35: =IF(S35="Paying",M35,"") | AC35: =IF(S35="Completed",M35,"")
A36: 46267 | B36: Vizada 通信订阅费（8月） | D36: TELEOCEAN INC | G36: 150 | H36: 1 | I36: =G36*H36 -> 150 | J36: 6000017 | K36: 46267 | L36: =I36 -> 150 | M36: =L36 -> 150 | Q36: 46267 | R36: 46282 | S36: Received | X36: =IF(S36="Accrual",M36,"") | Y36: =IF(S36="Receiving",M36,"") | Z36: =IF(S36="Received",M36,"") -> 150 | AA36: =IF(S36="Approved",M36,"") | AB36: =IF(S36="Paying",M36,"") | AC36: =IF(S36="Completed",M36,"")
A37: 46266 | B37: MSTS股份转移 | G37: 30622.61 | H37: 1 | I37: =G37*H37 -> 30622.61 | J37: 6000016 | L37: =I37 -> 30622.61 | M37: =L37 -> 30622.61 | S37: Completed | T37: 120 | X37: =IF(S37="Accrual",M37,"") | Y37: =IF(S37="Receiving",M37,"") | Z37: =IF(S37="Received",M37,"") | AA37: =IF(S37="Approved",M37,"") | AB37: =IF(S37="Paying",M37,"") | AC37: =IF(S37="Completed",M37,"") -> 30622.61
A38: 46266 | B38: 周老轨岚桥防船代理费用 | D38: CTM | G38: 120 | H38: 1 | I38: =G38*H38 -> 120 | J38: 6000001 | K38: =A38 -> 46266 | L38: =I38 -> 120 | M38: =L38 -> 120 | S38: Completed | X38: =IF(S38="Accrual",M38,"") | Y38: =IF(S38="Receiving",M38,"") | Z38: =IF(S38="Received",M38,"") | AA38: =IF(S38="Approved",M38,"") | AB38: =IF(S38="Paying",M38,"") | AC38: =IF(S38="Completed",M38,"") -> 120
A39: 46266 | B39: 岚桥加淡水200吨 | D39: CTM | G39: 1400 | H39: 1 | I39: =G39*H39 -> 1400 | J39: 6000001 | K39: =A39 -> 46266 | L39: =I39 -> 1400 | M39: =L39 -> 1400 | S39: Completed | X39: =IF(S39="Accrual",M39,"") | Y39: =IF(S39="Receiving",M39,"") | Z39: =IF(S39="Received",M39,"") | AA39: =IF(S39="Approved",M39,"") | AB39: =IF(S39="Paying",M39,"") | AC39: =IF(S39="Completed",M39,"") -> 1400
A40: 46266 | B40: 海事海关系统更改费用 | D40: CTM | G40: 375 | H40: 1 | I40: =G40*H40 -> 375 | J40: 6000011 | K40: =A40 -> 46266 | L40: =I40 -> 375 | M40: =L40 -> 375 | S40: Completed | X40: =IF(S40="Accrual",M40,"") | Y40: =IF(S40="Receiving",M40,"") | Z40: =IF(S40="Received",M40,"") | AA40: =IF(S40="Approved",M40,"") | AB40: =IF(S40="Paying",M40,"") | AC40: =IF(S40="Completed",M40,"") -> 375
...

Sheet CTM Expenses List
A1: 入账日期 | B1: 类型 | C1: Action | D1: Supplier | E1: PO Nos | F1: PO Current | G1: Rating | H1: PO Amount (USD) | I1: Account Code | J1: GRN/Date | K1: GRN Amount(USD) | L1: Invoice Amount(USD) | M1: Others | N1: Food | O1: Store | P1: Invoice Date | Q1: Due Date | R1: Payment Status | S1: Bank Charge | T1: Attachement | U1: Attachement | V1: Accrual | W1: Receiving | X1: Received | Y1: Approved | Z1: Paying | AA1: Completed
C2: Receiving | D2: Received | E2: Approved | F2: Paying | G2: Completed | H2: =SUM($H$3:H81) -> 29908 | K2: =SUM($K$3:K81) -> 29908 | L2: =SUM($L$3:L81) -> 29908 | M2: =SUM(M3:M121) -> 0 | N2: =SUM(N3:N121) -> 0 | O2: =SUM(O3:O121) -> 0 | S2: =SUM(S3:S29) -> 0 | T2: Invoices | U2: Credit Note | V2: =SUM($V$3:V81) -> 0 | W2: =SUM($W$3:W81) -> 0 | X2: =SUM(X3:X29) -> 0 | Y2: =SUM(Y3:Y29) -> 0 | Z2: =SUM(Z3:Z29) -> 0 | AA2: =SUM(AA3:AA29) -> 29908
V3: =IF(R3="Accrual",H3,"") | W3: =IF(R3="Receiving",K3,"") | X3: =IF(R3="Received",L3,"") | Y3: =IF(R3="Approved",L3,"") | Z3: =IF(R3="Paying",L3,"") | AA3: =IF(R3="Completed",L3,"")
A4: 46295 | B4: 9月份客餐费用支出 | C4: out | D4: CTM | F4: -249 | G4: 1 | H4: =F4*G4 -> -249 | I4: 6000002 | J4: =A4 -> 46295 | K4: =H4 -> -249 | L4: =K4 -> -249 | R4: Completed | T4: 9月份客餐费用支出249美元.pdf | V4: =IF(R4="Accrual",H4,"") | W4: =IF(R4="Receiving",K4,"") | X4: =IF(R4="Received",L4,"") | Y4: =IF(R4="Approved",L4,"") | Z4: =IF(R4="Paying",L4,"") | AA4: =IF(R4="Completed",L4,"") -> -249
A5: 46295 | B5: 9月份全船伙食费支出 | C5: out | D5: CTM | F5: -5592 | G5: 1 | H5: =F5*G5 -> -5592 | I5: 1000002 | J5: =A5 -> 46295 | K5: =H5 -> -5592 | L5: =K5 -> -5592 | R5: Completed | T5: 2026年9月份伙食费收据5592美元.pdf | V5: =IF(R5="Accrual",H5,"") | W5: =IF(R5="Receiving",K5,"") | X5: =IF(R5="Received",L5,"") | Y5: =IF(R5="Approved",L5,"") | Z5: =IF(R5="Paying",L5,"") | AA5: =IF(R5="Completed",L5,"") -> -5592
A6: 46286 | B6: 柯凯敏青岛就医及路费支出 | C6: out | D6: CTM | F6: -149 | G6: 1 | H6: =F6*G6 -> -149 | I6: 7000009 | J6: =A6 -> 46286 | K6: =H6 -> -149 | L6: =K6 -> -149 | R6: Completed | T6: 柯凯敏青岛就医及路费支出149美元.pdf | V6: =IF(R6="Accrual",H6,"") | W6: =IF(R6="Receiving",K6,"") | X6: =IF(R6="Received",L6,"") | Y6: =IF(R6="Approved",L6,"") | Z6: =IF(R6="Paying",L6,"") | AA6: =IF(R6="Completed",L6,"") -> -149
A7: 46286 | B7: 678月季度自修奖金支出 | C7: out | D7: CTM | F7: -3000 | G7: 1 | H7: =F7*G7 -> -3000 | I7: 10000007 | J7: =A7 -> 46286 | K7: =H7 -> -3000 | L7: =K7 -> -3000 | R7: Completed | T7: 678月自修奖金支出3000美元.pdf | V7: =IF(R7="Accrual",H7,"") | W7: =IF(R7="Receiving",K7,"") | X7: =IF(R7="Received",L7,"") | Y7: =IF(R7="Approved",L7,"") | Z7: =IF(R7="Paying",L7,"") | AA7: =IF(R7="Completed",L7,"") -> -3000
A8: 46284 | B8: 青岛代理收 SPRO费用300美元 | C8: out | D8: CTM | F8: -300 | G8: 1 | H8: =F8*G8 -> -300 | I8: 6000001 | J8: =A8 -> 46284 | K8: =H8 -> -300 | L8: =K8 -> -300 | R8: Completed | T8: 青岛代理收SPRO 费用300美元.pdf | V8: =IF(R8="Accrual",H8,"") | W8: =IF(R8="Receiving",K8,"") | X8: =IF(R8="Received",L8,"") | Y8: =IF(R8="Approved",L8,"") | Z8: =IF(R8="Paying",L8,"") | AA8: =IF(R8="Completed",L8,"") -> -300
A9: 46284 | B9: 青岛购买BondedStore香烟 | C9: out | D9: CTM | F9: -1010 | G9: 1 | H9: =F9*G9 -> -1010 | I9: 6000020 | J9: =A9 -> 46284 | K9: =H9 -> -1010 | L9: =K9 -> -1010 | R9: Completed | T9: 青岛购买Bonded Store香烟1010美元.pdf | V9: =IF(R9="Accrual",H9,"") | W9: =IF(R9="Receiving",K9,"") | X9: =IF(R9="Received",L9,"") | Y9: =IF(R9="Approved",L9,"") | Z9: =IF(R9="Paying",L9,"") | AA9: =IF(R9="Completed",L9,"") -> -1010
A10: 46283 | B10: 日照购买Bonded Store酒水等支出 | C10: out | D10: CTM | F10: -293 | G10: 1 | H10: =F10*G10 -> -293 | I10: 6000020 | J10: =A10 -> 46283 | K10: =H10 -> -293 | L10: =K10 -> -293 | R10: Completed | T10: 日照购买Bonded Store酒水等支出293美元.pdf | V10: =IF(R10="Accrual",H10,"") | W10: =IF(R10="Receiving",K10,"") | X10: =IF(R10="Received",L10,"") | Y10: =IF(R10="Approved",L10,"") | Z10: =IF(R10="Paying",L10,"") | AA10: =IF(R10="Completed",L10,"") -> -293
A11: 46266 | B11: 周老轨岚桥防船代理费用 | C11: out | D11: CTM | F11: -120 | G11: 1 | H11: =F11*G11 -> -120 | I11: 6000001 | J11: =A11 -> 46266 | K11: =H11 -> -120 | L11: =K11 -> -120 | R11: Completed | T11: 机务访船代理费120美元.pdf | V11: =IF(R11="Accrual",H11,"") | W11: =IF(R11="Receiving",K11,"") | X11: =IF(R11="Received",L11,"") | Y11: =IF(R11="Approved",L11,"") | Z11: =IF(R11="Paying",L11,"") | AA11: =IF(R11="Completed",L11,"") -> -120
A12: 46266 | B12: 岚桥加淡水200吨 | C12: out | D12: CTM | F12: -1400 | G12: 1 | H12: =F12*G12 -> -1400 | I12: 6000001 | J12: =A12 -> 46266 | K12: =H12 -> -1400 | L12: =K12 -> -1400 | R12: Completed | T12: 岚桥加淡水费用1400美元.pdf | V12: =IF(R12="Accrual",H12,"") | W12: =IF(R12="Receiving",K12,"") | X12: =IF(R12="Received",L12,"") | Y12: =IF(R12="Approved",L12,"") | Z12: =IF(R12="Paying",L12,"") | AA12: =IF(R12="Completed",L12,"") -> -1400
A13: 46266 | B13: 海事海关系统更改费用 | C13: out | D13: CTM | F13: -375 | G13: 1 | H13: =F13*G13 -> -375 | I13: 6000011 | J13: =A13 -> 46266 | K13: =H13 -> -375 | L13: =K13 -> -375 | R13: Completed | T13: 海事海关系统更改费用375美元.pdf | V13: =IF(R13="Accrual",H13,"") | W13: =IF(R13="Receiving",K13,"") | X13: =IF(R13="Received",L13,"") | Y13: =IF(R13="Approved",L13,"") | Z13: =IF(R13="Paying",L13,"") | AA13: =IF(R13="Completed",L13,"") -> -375
A14: 46265 | B14: 8月份客餐费用支出 | C14: out | D14: CTM | F14: -662 | G14: 1 | H14: =F14*G14 -> -662 | I14: 1000002 | J14: =A14 -> 46265 | K14: =H14 -> -662 | L14: =K14 -> -662 | R14: Completed | T14: 8月份客餐费用支出.pdf | V14: =IF(R14="Accrual",H14,"") | W14: =IF(R14="Receiving",K14,"") | X14: =IF(R14="Received",L14,"") | Y14: =IF(R14="Approved",L14,"") | Z14: =IF(R14="Paying",L14,"") | AA14: =IF(R14="Completed",L14,"") -> -662
A15: 46265 | B15: 8月份全船伙食费支出 | C15: out | D15: CTM | F15: -5400 | G15: 1 | H15: =F15*G15 -> -5400 | I15: 1000002 | J15: =A15 -> 46265 | K15: =H15 -> -5400 | L15: =K15 -> -5400 | R15: Completed | T15: 8月份船员伙食费用支出.pdf | V15: =IF(R15="Accrual",H15,"") | W15: =IF(R15="Receiving",K15,"") | X15: =IF(R15="Received",L15,"") | Y15: =IF(R15="Approved",L15,"") | Z15: =IF(R15="Paying",L15,"") | AA15: =IF(R15="Completed",L15,"") -> -5400
A16: 46257 | B16: HOMONHON水手张善钧购药支出 | C16: out | D16: CTM | F16: -733 | G16: 1 | H16: =F16*G16 -> -733 | I16: 1000006 | J16: =A16 -> 46257 | K16: =H16 -> -733 | L16: =K16 -> -733 | R16: Completed | T16: HOMONHON张善钧购药支出.pdf | W16: =IF(R16="Receiving",K16,"") | X16: =IF(R16="Received",L16,"") | Y16: =IF(R16="Approved",L16,"") | Z16: =IF(R16="Paying",L16,"") | AA16: =IF(R16="Completed",L16,"") -> -733
A17: 46251 | B17: V2605扫洗舱劳务费 | C17: out | D17: CTM | F17: -1125 | G17: 1 | H17: =F17*G17 -> -1125 | I17: 9000001 | J17: =A17 -> 46251 | K17: =H17 -> -1125 | L17: =K17 -> -1125 | R17: Completed | T17: PAYMENT LIST OF V2605 HOLD CLEANING BONUS.pdf | W17: =IF(R17="Receiving",K17,"") | X17: =IF(R17="Received",L17,"") | Y17: =IF(R17="Approved",L17,"") | Z17: =IF(R17="Paying",L17,"") | AA17: =IF(R17="Completed",L17,"") -> -1125
A18: 46238 | B18: 交付船长备用金 | C18: In | D18: CTM | F18: 50000 | G18: 1 | H18: =F18*G18 -> 50000 | I18: 6000007 | J18: 12‑Aug‑26 | K18: =H18 -> 50000 | L18: =K18 -> 50000 | R18: Completed | T18: CTM 50000USD RECEIPT.pdf | W18: =IF(R18="Receiving",K18,"") | X18: =IF(R18="Received",L18,"") | Y18: =IF(R18="Approved",L18,"") | Z18: =IF(R18="Paying",L18,"") | AA18: =IF(R18="Completed",L18,"") -> 50000
A19: 46238 | B19: 改船籍港特殊劳务费200美元 | C19: out | D19: CTM | F19: -200 | G19: 1 | H19: =F19*G19 -> -200 | I19: 9990001 | J19: 46238 | K19: =H19 -> -200 | L19: =K19 -> -200 | R19: Completed | T19: 改船籍港特殊劳务费200美元.pdf | V19: =IF(R19="Accrual",H19,"") | W19: =IF(R19="Receiving",K19,"") | X19: =IF(R19="Received",L19,"") | Y19: =IF(R19="Approved",L19,"") | Z19: =IF(R19="Paying",L19,"") | AA19: =IF(R19="Completed",L19,"") -> -200
A20: 46237 | B20: 原船管欠船员7月份伙食费支出 | C20: out | D20: CTM | F20: -1544 | G20: 1 | H20: =F20*G20 -> -1544 | I20: 1000002 | J20: 46237 | K20: =H20 -> -1544 | L20: =K20 -> -1544 | R20: Completed | T20: 7月份原船管伙食欠款1544美元收据 | V20: =IF(R20="Accrual",H20,"") | W20: =IF(R20="Receiving",K20,"") | X20: =IF(R20="Received",L20,"") | Y20: =IF(R20="Approved",L20,"") | Z20: =IF(R20="Paying",L20,"") | AA20: =IF(R20="Completed",L20,"") -> -1544
A21: 46235 | B21: LR船检两名外锚地登离船代理费用支出 | C21: out | D21: CTM | F21: -9230 | G21: 1 | H21: =F21*G21 -> -9230 | I21: 9990001 | J21: 46236 | K21: =H21 -> -9230 | L21: =K21 -> -9230 | R21: Completed | T21: LR 两名船检猫的登离船代理费用支出.pdf | V21: =IF(R21="Accrual",H21,"") | W21: =IF(R21="Receiving",K21,"") | X21: =IF(R21="Received",L21,"") | Y21: =IF(R21="Approved",L21,"") | Z21: =IF(R21="Paying",L21,"") | AA21: =IF(R21="Completed",L21,"") -> -9230
A22: 46234 | B22: GMDSS年检共工程师登离船代理费用支出 | C22: out | D22: CTM | F22: -2150 | G22: 1 | H22: =F22*G22 -> -2150 | I22: 9990001 | J22: 46235 | K22: =H22 -> -2150 | L22: =K22 -> -2150 | R22: Completed | T22: GMDSS年检工程师登离轮代理费支出.pdf | V22: =IF(R22="Accrual",H22,"") | W22: =IF(R22="Receiving",K22,"") | X22: =IF(R22="Received",L22,"") | Y22: =IF(R22="Approved",L22,"") | Z22: =IF(R22="Paying",L22,"") | AA22: =IF(R22="Completed",L22,"") -> -2150
A23: 46234 | B23: GRESIK加淡水100吨 | C23: out | D23: CTM | F23: -1350 | G23: 1 | H23: =F23*G23 -> -1350 | I23: 6000001 | J23: 46234 | K23: =H23 -> -1350 | L23: =K23 -> -1350 | R23: Completed | T23: Gresik加淡水100吨.pdf | V23: =IF(R23="Accrual",H23,"") | W23: =IF(R23="Receiving",K23,"") | X23: =IF(R23="Received",L23,"") | Y23: =IF(R23="Approved",L23,"") | Z23: =IF(R23="Paying",L23,"") | AA23: =IF(R23="Completed",L23,"") -> -1350
A24: 46233 | B24: 制作新船章两枚 | C24: out | D24: CTM | F24: -25 | G24: 1 | H24: =F24*G24 -> -25 | I24: 6000013 | J24: 46233 | K24: =H24 -> -25 | L24: =K24 -> -25 | R24: Completed | T24: 制作两枚船章.pdf | AA24: =IF(R24="Completed",L24,"") -> -25
A25: 46233 | B25: CTM RMB100,000 hand carried onboard when tookover vessel≈14815美元 | C25: In | D25: CTM | F25: 14815 | G25: 1 | H25: =F25*G25 -> 14815 | I25: 6000007 | J25: 46233 | K25: =H25 -> 14815 | L25: =K25 -> 14815 | R25: Completed | T25: 备用金收据14815USD.pdf | V25: =IF(R25="Accrual",H25,"") | W25: =IF(R25="Receiving",K25,"") | X25: =IF(R25="Received",L25,"") | Y25: =IF(R25="Approved",L25,"") | Z25: =IF(R25="Paying",L25,"") | AA25: =IF(R25="Completed",L25,"") -> 14815

Sheet Shipmanagement Cost
A1: 入账日期 | B1: 类型 | C1: RQA | D1: Supplier | E1: PO Nos | F1: Pay. Approval | G1: PO Current | H1: Rating | I1: PO Amount (USD) | J1: Account Code | K1: GRN/Date | L1: GRN Amount(USD) | M1: Invoice Amount(USD) | N1: C/N,Accural | O1: C/N Profit | P1: Profit | Q1: Invoice Date | R1: Due Date | S1: Payment Status | T1: Bank Charge | U1: Bank Slip | V1: Attachement | W1: Accrual | X1: Receiving | Y1: Received | Z1: Approved | AA1: Paying | AB1: Completed
C2: Receiving | D2: Received | E2: Approved | G2: Paying | H2: Completed | I2: =SUM($I$4:I161) -> 371476.96 | L2: =SUM($L$4:L161) -> 371476.96 | M2: =SUM($M$4:M161) -> 371321.3 | N2: =SUM(N3:N154) -> 0 | O2: =SUM(O3:O154) -> 0 | P2: =SUM(P3:P154) -> 0 | T2: =SUM(T3:T114) -> 920.53 | V2: Invoices | W2: =SUM(W4:W114) -> 6868.04 | X2: =SUM(X4:X114) -> 0 | Y2: =SUM(Y4:Y114) -> 108730.2 | Z2: =SUM(Z4:Z114) -> 0 | AA2: =SUM(AA4:AA114) -> 0 | AB2: =SUM(AB4:AB114) -> 192452.06 | AC2: =SUM(W2:AB2)+T2 -> 308970.83
A3: 46265 | B3: CTM 月度船上结余 | D3: MSTS | G3: ='CTM Expenses List'!AA2 -> 29908 | H3: 1 | I3: =-G3 -> -29908 | J3: 6000007 | K3: 46265 | L3: =I3 -> -29908 | M3: =L3 -> -29908 | S3: Completed | W3: =IF(S3="Receiving",M3,"") | X3: =IF(S3="Received",M3,"") | Y3: =IF(S3="Approved",M3,"") | Z3: =IF(S3="Paying",M3,"") | AA3: =IF(S3="Paying",M3,"") | AB3: =IF(S3="Completed",M3,"") -> -29908
AB4: =IF(S4="Completed",M4,"")
A5: 46309 | B5: 9月份船员工资+其他费用 | D5: Top Marine Limited | G5: 77881.96 | H5: 1 | I5: =G5*H5 -> 77881.96 | J5: 1000001 | K5: =A5 -> 46309 | L5: =I5 -> 77881.96 | M5: =L5 -> 77881.96 | S5: Received | V5: PIONEER LADY 9月账单(1).pdf | Y5: =IF(S5="Received",M5,"") -> 77881.96 | AB5: =IF(S5="Completed",M5,"")
A6: 46295 | B6: 帮Libra-XS支付巴哈马年度国旗国检验 | D6: SIMINTEC | G6: 2600 | H6: 1 | I6: =G6*H6 -> 2600 | L6: =I6 -> 2600 | M6: =I6 -> 2600 | S6: Completed | T6: 20 | U6: Payment_Certificate_20260930094805(1).pdf | Y6: =IF(S6="Received",M6,"") | AB6: =IF(S6="Completed",M6,"") -> 2600
A7: 46295 | B7: 9月份全船伙食费支出 | D7: CTM | G7: 5592 | H7: 1 | I7: =G7*H7 -> 5592 | J7: 1000002 | K7: =A7 -> 46295 | L7: =I7 -> 5592 | M7: =I7 -> 5592 | S7: Completed | V7: 2026年9月份伙食费收据5592美元.pdf | W7: =IF(S7="Accrual",M7,"") | X7: =IF(S7="Receiving",M7,"") | Y7: =IF(S7="Received",M7,"") | Z7: =IF(S7="Approved",M7,"") | AA7: =IF(S7="Paying",M7,"") | AB7: =IF(S7="Completed",M7,"") -> 5592
A8: 46293 | B8: 借款给 MULAU SHIPMANAGEMENT (HK) LIMITED付款失败 | D8: Maritime Solutions Technology Services (HK) Limited | G8: -9500 | H8: 1 | I8: =G8*H8 -> -9500 | L8: =I8 -> -9500 | M8: =I8 -> -9500 | S8: Completed | T8: -20 | Y8: =IF(S8="Received",M8,"") | AB8: =IF(S8="Completed",M8,"") -> -9500
A9: 46293 | B9: 借款给 MULAU SHIPMANAGEMENT (HK) LIMITED | D9: Maritime Solutions Technology Services (HK) Limited | G9: 9500 | H9: 1 | I9: =G9*H9 -> 9500 | L9: =I9 -> 9500 | M9: =L9 -> 9500 | S9: Completed | T9: 20 | W9: =IF(S9="Accrual",M9,"") | X9: =IF(S9="Receiving",M9,"") | Y9: =IF(S9="Received",M9,"") | Z9: =IF(S9="Approved",M9,"") | AA9: =IF(S9="Paying",M9,"") | AB9: =IF(S9="Completed",M9,"") -> 9500
A10: 46289 | B10: PIONEER LADY_海卫通卫星通信服务费 | D10: Marinesat海卫通网络科技有限公司 | G10: 8487.98 | H10: 0.149 | I10: =G10*H10 -> 1264.709 | J10: 6000017 | L10: =I10 -> 1264.709 | M10: =L10 -> 1264.709 | S10: Received | V10: SC0026080016-PIONEER LADY-Maritime Solutions Technology Service (HK) Limited-20260831.pdf | W10: =IF(S10="Accrual",M10,"") | X10: =IF(S10="Receiving",M10,"") | Y10: =IF(S10="Received",M10,"") -> 1264.709 | Z10: =IF(S10="Approved",M10,"") | AA10: =IF(S10="Paying",M10,"") | AB10: =IF(S10="Completed",M10,"")
A11: 46289 | B11: PIONEER LADY_办公租赁费+薪资 | D11: Maritime Solutions Technology Services (HK) Limited | G11: =157197.89+70000 -> 227197.89 | H11: 0.14937855 | I11: =G11*H11 -> 33938.492 | J11: 6000016 | L11: =I11 -> 33938.492 | M11: =L11 -> 33938.492 | S11: Completed | T11: 120 | U11: 20260930周总提现30000USD.pdf | V11: Invoice--单船开形式发票-Pioneer Lady办公室租金+员工薪资.pdf | W11: =IF(S11="Accrual",M11,"") | X11: =IF(S11="Receiving",M11,"") | Y11: =IF(S11="Received",M11,"") | Z11: =IF(S11="Approved",M11,"") | AA11: =IF(S11="Paying",M11,"") | AB11: =IF(S11="Completed",M11,"") -> 33938.492
A12: 46286 | B12: 2026年6,7,8月季度自修奖金支出 | D12: CTM | G12: 1000 | H12: 1 | I12: =G12*H12 -> 1000 | J12: 10000007 | K12: =A12 -> 46286 | L12: =I12 -> 1000 | M12: =L12 -> 1000 | S12: Completed | V12: 678月自修奖金支出3000美元.pdf | W12: =IF(S12="Accrual",M12,"") | X12: =IF(S12="Receiving",M12,"") | Y12: =IF(S12="Received",M12,"") | Z12: =IF(S12="Approved",M12,"") | AA12: =IF(S12="Paying",M12,"") | AB12: =IF(S12="Completed",M12,"") -> 1000
A13: 46286 | B13: 柯凯敏青岛就医及路费支出 | D13: CTM | G13: 149 | H13: 1 | I13: =G13*H13 -> 149 | J13: 7000009 | K13: =A13 -> 46286 | L13: =I13 -> 149 | M13: =L13 -> 149 | S13: Completed | V13: 柯凯敏青岛就医及路费支出149美元.pdf | W13: =IF(S13="Accrual",M13,"") | X13: =IF(S13="Receiving",M13,"") | Y13: =IF(S13="Received",M13,"") | Z13: =IF(S13="Approved",M13,"") | AA13: =IF(S13="Paying",M13,"") | AB13: =IF(S13="Completed",M13,"") -> 149
A14: 46284 | B14: 青岛代理收 SPRO费用300美元 | D14: CTM | G14: 300 | H14: 1 | I14: =G14*H14 -> 300 | J14: 6000001 | K14: =A14 -> 46284 | L14: =I14 -> 300 | M14: =L14 -> 300 | S14: Completed | V14: 青岛代理收SPRO 费用300美元.pdf | W14: =IF(S14="Accrual",M14,"") | X14: =IF(S14="Receiving",M14,"") | Y14: =IF(S14="Received",M14,"") | Z14: =IF(S14="Approved",M14,"") | AA14: =IF(S14="Paying",M14,"") | AB14: =IF(S14="Completed",M14,"") -> 300
A15: 46284 | B15: 青岛购买BondedStore香烟 | D15: CTM | G15: 1010 | H15: 1 | I15: =G15*H15 -> 1010 | J15: 6000020 | K15: =A15 -> 46284 | L15: =I15 -> 1010 | M15: =L15 -> 1010 | S15: Completed | V15: 青岛购买Bonded Store香烟1010美元.pdf | W15: =IF(S15="Accrual",M15,"") | X15: =IF(S15="Receiving",M15,"") | Y15: =IF(S15="Received",M15,"") | Z15: =IF(S15="Approved",M15,"") | AA15: =IF(S15="Paying",M15,"") | AB15: =IF(S15="Completed",M15,"") -> 1010
A16: 46283 | B16: 日照购买Bonded Store酒水等支出 | D16: CTM | G16: 293 | H16: 1 | I16: =G16*H16 -> 293 | J16: 6000020 | K16: =A16 -> 46283 | L16: =I16 -> 293 | M16: =L16 -> 293 | S16: Completed | V16: 日照购买Bonded Store酒水等支出293美元(1).pdf | W16: =IF(S16="Accrual",M16,"") | X16: =IF(S16="Receiving",M16,"") | Y16: =IF(S16="Received",M16,"") | Z16: =IF(S16="Approved",M16,"") | AA16: =IF(S16="Paying",M16,"") | AB16: =IF(S16="Completed",M16,"") -> 293
B17: 冲回原船管欠船员7月份伙食费支出 | D17: MSTS | G17: -1544 | H17: 1 | I17: -1544 | J17: 6000007 | L17: -1544 | M17: -1544 | W17: =IF(S17="Accrual",M17,"") | X17: =IF(S17="Receiving",M17,"") | Y17: =IF(S17="Received",M17,"") | Z17: =IF(S17="Approved",M17,"") | AA17: =IF(S17="Paying",M17,"") | AB17: =IF(S17="Completed",M17,"")
A18: 46277 | B18: 办公室杂项费用 | D18: Maritime Solutions Technology Services (HK) Limited | G18: 298.31 | H18: 1 | I18: =G18*H18 -> 298.31 | J18: 6000016 | L18: =I18 -> 298.31 | M18: =L18 -> 298.31 | S18: Completed | V18: 办公室费用-深圳博远20260922--$298.31(2).pdf | W18: =IF(S18="Accrual",M18,"") | X18: =IF(S18="Receiving",M18,"") | Y18: =IF(S18="Received",M18,"") | Z18: =IF(S18="Approved",M18,"") | AA18: =IF(S18="Paying",M18,"") | AB18: =IF(S18="Completed",M18,"") -> 298.31
A19: 46274 | B19: Pioneer Lady岚桥港值班及交通补贴-周琦RMB3541.02 | D19: Maritime Solutions Technology Services (HK) Limited | G19: 522.51 | H19: 1 | I19: =G19*H19 -> 522.51 | J19: 6000006 | L19: =I19 -> 522.51 | M19: =L19 -> 522.51 | S19: Completed | V19: Pioneer Lady蓝桥港值班津贴_20260909(1).pdf | W19: =IF(S19="Accrual",M19,"") | X19: =IF(S19="Receiving",M19,"") | Y19: =IF(S19="Received",M19,"") | Z19: =IF(S19="Approved",M19,"") | AA19: =IF(S19="Paying",M19,"") | AB19: =IF(S19="Completed",M19,"") -> 522.51
A20: 46269 | B20: 2026年8 月份船员工资 | D20: Top Marine Limited | G20: 70197.08 | H20: 1 | I20: =G20*H20 -> 70197.08 | J20: 1000001 | L20: =I20 -> 70197.08 | M20: =L20 -> 70197.08 | S20: Completed | T20: 170.53 | U20: Payment_Certificate_20260911154058.pdf | V20: PIONEER LADY 8月船员工资(2).pdf | W20: =IF(S20="Accrual",M20,"") | X20: =IF(S20="Receiving",M20,"") | Y20: =IF(S20="Received",M20,"") | Z20: =IF(S20="Approved",M20,"") | AA20: =IF(S20="Paying",M20,"") | AB20: =IF(S20="Completed",M20,"") -> 70197.08
A21: 46267 | B21: 通信数据流量费 | D21: TELEOCEAN INC | G21: 44.8 | H21: 1 | I21: =G21*H21 -> 44.8 | J21: 6000017 | K21: 46266 | L21: =I21 -> 44.8 | M21: =L21 -> 44.8 | Q21: 46266 | R21: 46281 | S21: Received | V21: Invoice_PIONEER LADY_C_2026_08_21358741_Stratos.pdf | W21: =IF(S21="Accrual",M21,"") | X21: =IF(S21="Receiving",M21,"") | Y21: =IF(S21="Received",M21,"") -> 44.8 | Z21: =IF(S21="Approved",M21,"") | AA21: =IF(S21="Paying",M21,"") | AB21: =IF(S21="Completed",M21,"")
A22: 46267 | B22: Vizada 通信订阅费（8月） | D22: TELEOCEAN INC | G22: 150 | H22: 1 | I22: =G22*H22 -> 150 | J22: 6000017 | K22: 46267 | L22: =I22 -> 150 | M22: =L22 -> 150 | Q22: 46267 | R22: 46282 | S22: Received | V22: Invoice_PIONEER LADY_C Monthly_2026_08_21363280_Stratos.pdf | W22: =IF(S22="Accrual",M22,"") | X22: =IF(S22="Receiving",M22,"") | Y22: =IF(S22="Received",M22,"") -> 150 | Z22: =IF(S22="Approved",M22,"") | AA22: =IF(S22="Paying",M22,"") | AB22: =IF(S22="Completed",M22,"")
A23: 46267 | B23: 提现后的差额费用 | D23: Maritime Solutions Technology Services (HK) Limited | G23: 2301.47 | H23: 1 | I23: =G23*H23 -> 2301.47 | J23: 6000016 | L23: =I23 -> 2301.47 | M23: =L23 -> 2301.47 | S23: Completed | U23: 20260831周总提现5000USD(1).pdf | V23: 提现后差额费用--2026.08.31(2).pdf | W23: =IF(S23="Accrual",M23,"") | X23: =IF(S23="Receiving",M23,"") | Y23: =IF(S23="Received",M23,"") | Z23: =IF(S23="Approved",M23,"") | AA23: =IF(S23="Paying",M23,"") | AB23: =IF(S23="Completed",M23,"") -> 2301.47
A24: 46267 | B24: 办公室费用 | D24: Maritime Solutions Technology Services (HK) Limited | G24: 10292.19 | H24: 1 | I24: =G24*H24 -> 10292.19 | J24: 6000013 | L24: =I24 -> 10292.19 | M24: =L24 -> 10292.19 | S24: Completed | V24: 办公费用69527.18RMB—10292.19USD(2).pdf | W24: =IF(S24="Accrual",M24,"") | X24: =IF(S24="Receiving",M24,"") | Y24: =IF(S24="Received",M24,"") | Z24: =IF(S24="Approved",M24,"") | AA24: =IF(S24="Paying",M24,"") | AB24: =IF(S24="Completed",M24,"") -> 10292.19
A25: 46266 | B25: MSTS股份转移 | D25: Maritime Solutions Technology Services (HK) Limited | G25: 30622.61 | H25: 1 | I25: =G25*H25 -> 30622.61 | J25: 6000016 | L25: =I25 -> 30622.61 | M25: =L25 -> 30622.61 | S25: Completed | T25: 120 | U25: Payment_Certificate_20260920113437.pdf | V25: Invoice--单船开形式发票-段正权股份(1).pdf | W25: =IF(S25="Accrual",M25,"") | X25: =IF(S25="Receiving",M25,"") | Y25: =IF(S25="Received",M25,"") | Z25: =IF(S25="Approved",M25,"") | AA25: =IF(S25="Paying",M25,"") | AB25: =IF(S25="Completed",M25,"") -> 30622.61
A26: 46266 | B26: 周老轨岚桥防船代理费用 | D26: CTM | F26: 机务访船代理费120美元.pdf | G26: 120 | H26: 1 | I26: =G26*H26 -> 120 | J26: 6000001 | K26: =A26 -> 46266 | L26: =I26 -> 120 | M26: =L26 -> 120 | S26: Completed | V26: 机务访船代理费120美元.pdf | W26: =IF(S26="Accrual",M26,"") | X26: =IF(S26="Receiving",M26,"") | Y26: =IF(S26="Received",M26,"") | Z26: =IF(S26="Approved",M26,"") | AA26: =IF(S26="Paying",M26,"") | AB26: =IF(S26="Completed",M26,"") -> 120
